Workbook
Name ReleaseList: Releases[Release]

Sheet Summary
C2: Project Functional Development
C4: Proyecto | D4: Portal Agentes | G4: Cliente | H4: Esteve
C5: Owner | D5: Alex Olivé | G5: Fecha
C8: Functional Summary
D9: Total | E9: Pending | F9: In progress | G9: Finished
C10: Requirements | D10: =D17 -> 31 | E10: =E17 -> 31 | F10: =F17 -> 0 | G10: =G17+H17 -> 0
C11: Features - Design | D11: =D30 -> #REF! | E11: =E30 -> #REF! | F11: =F30 -> #REF! | G11: =G30 -> #REF!
C12: Features - Validation | D12: =D42 -> #REF! | E12: =E42 -> #REF! | F12: =F42 -> #REF! | G12: =G42 -> #REF!
C13: UATs | D13: =SUM(E13:G13) -> 8 | E13: =COUNTIF(UATS[Status],"=Planned") -> 8 | F13: =COUNTIF(UATS[Status],"=Validating") -> 0 | G13: =COUNTIF(UATS[Status],"=Finished") -> 0
C14: Releases | D14: =SUM(E14:G14) -> 5 | E14: =COUNTIF(Releases[Status],"=Planned") -> 4 | F14: =COUNTIF(Releases[Status],"=Validating") -> 0 | G14: =COUNTIF(Releases[Status],"=Finished") -> 1
C17: Requirements | D17: =SUM(E17:H17) -> 31 | E17: =COUNTIF(Requirements[Status],"="&E18) -> 31 | F17: =COUNTIF(Requirements[Status],"="&F18) -> 0 | G17: =COUNTIF(Requirements[Status],"="&G18) -> 0 | H17: =COUNTIF(Requirements[Status],"="&H18) -> 0
D18: Total | E18: Pending | F18: Reviewing | G18: Included | H18: Not Included
C19: by Type | E19: =SUM(E20:E23) -> 28 | F19: =SUM(F20:F23) -> 0 | G19: =SUM(G20:G23) -> 0 | H19: =SUM(H20:H23) -> 0
D20: Business | E20: =COUNTIFS(Requirements[Type],"="&$D20, Requirements[Status], "="&E$18) -> 6 | F20: =COUNTIFS(Requirements[Type],"="&$D20, Requirements[Status], "="&F$18) -> 0 | G20: =COUNTIFS(Requirements[Type],"="&$D20, Requirements[Status], "="&G$18) -> 0 | H20: =COUNTIFS(Requirements[Type],"="&$D20, Requirements[Status], "="&H$18) -> 0
D21: User | E21: =COUNTIFS(Requirements[Type],"="&$D21, Requirements[Status], "="&E$18) -> 17 | F21: =COUNTIFS(Requirements[Type],"="&$D21, Requirements[Status], "="&F$18) -> 0 | G21: =COUNTIFS(Requirements[Type],"="&$D21, Requirements[Status], "="&G$18) -> 0 | H21: =COUNTIFS(Requirements[Type],"="&$D21, Requirements[Status], "="&H$18) -> 0
D22: Technology | E22: =COUNTIFS(Requirements[Type],"="&$D22, Requirements[Status], "="&E$18) -> 5 | F22: =COUNTIFS(Requirements[Type],"="&$D22, Requirements[Status], "="&F$18) -> 0 | G22: =COUNTIFS(Requirements[Type],"="&$D22, Requirements[Status], "="&G$18) -> 0 | H22: =COUNTIFS(Requirements[Type],"="&$D22, Requirements[Status], "="&H$18) -> 0
D23: Lifecycle | E23: =COUNTIFS(Requirements[Type],"="&$D23, Requirements[Status], "="&E$18) -> 0 | F23: =COUNTIFS(Requirements[Type],"="&$D23, Requirements[Status], "="&F$18) -> 0 | G23: =COUNTIFS(Requirements[Type],"="&$D23, Requirements[Status], "="&G$18) -> 0 | H23: =COUNTIFS(Requirements[Type],"="&$D23, Requirements[Status], "="&H$18) -> 0
C24: by Priority | E24: =SUM(E25:E28) -> 31 | F24: =SUM(F25:F28) -> 0 | G24: =SUM(G25:G28) -> 0 | H24: =SUM(H25:H28) -> 0
D25: Must have | E25: =COUNTIFS(Requirements[Priority],"="&$D25, Requirements[Status], "="&E$18) -> 25 | F25: =COUNTIFS(Requirements[Priority],"="&$D25, Requirements[Status], "="&F$18) -> 0 | G25: =COUNTIFS(Requirements[Priority],"="&$D25, Requirements[Status], "="&G$18) -> 0 | H25: =COUNTIFS(Requirements[Priority],"="&$D25, Requirements[Status], "="&H$18) -> 0
D26: Should have | E26: =COUNTIFS(Requirements[Priority],"="&$D26, Requirements[Status], "="&E$18) -> 4 | F26: =COUNTIFS(Requirements[Priority],"="&$D26, Requirements[Status], "="&F$18) -> 0 | G26: =COUNTIFS(Requirements[Priority],"="&$D26, Requirements[Status], "="&G$18) -> 0 | H26: =COUNTIFS(Requirements[Priority],"="&$D26, Requirements[Status], "="&H$18) -> 0
D27: Could have | E27: =COUNTIFS(Requirements[Priority],"="&$D27, Requirements[Status], "="&E$18) -> 2 | F27: =COUNTIFS(Requirements[Priority],"="&$D27, Requirements[Status], "="&F$18) -> 0 | G27: =COUNTIFS(Requirements[Priority],"="&$D27, Requirements[Status], "="&G$18) -> 0 | H27: =COUNTIFS(Requirements[Priority],"="&$D27, Requirements[Status], "="&H$18) -> 0
D28: Will not have | E28: =COUNTIFS(Requirements[Priority],"="&$D28, Requirements[Status], "="&E$18) -> 0 | F28: =COUNTIFS(Requirements[Priority],"="&$D28, Requirements[Status], "="&F$18) -> 0 | G28: =COUNTIFS(Requirements[Priority],"="&$D28, Requirements[Status], "="&G$18) -> 0 | H28: =COUNTIFS(Requirements[Priority],"="&$D28, Requirements[Status], "="&H$18) -> 0
C30: Features Design | D30: =SUM(E30:H30) -> #REF! | E30: =COUNTIF(#REF!,"="&E31) -> #REF! | F30: =COUNTIF(#REF!,"="&F31) -> #REF! | G30: =COUNTIF(#REF!,"="&G31) -> #REF! | H30: =COUNTIF(#REF!,"="&H31) -> #REF!
D31: Total | E31: Pending | F31: Reviewing | G31: Included | H31: Not Included
C32: by Area | E32: =SUM(E33:E40) -> #REF! | F32: =SUM(F33:F40) -> #REF! | G32: =SUM(G33:G40) -> #REF! | H32: =SUM(H33:H40) -> #REF!
D33: Navigation | E33: =COUNTIFS(Features[Area],"="&$D33,#REF!, "="&E$31) -> #REF! | F33: =COUNTIFS(Features[Area],"="&$D33,#REF!, "="&F$31) -> #REF! | G33: =COUNTIFS(Features[Area],"="&$D33,#REF!, "="&G$31) -> #REF! | H33: =COUNTIFS(Features[Area],"="&$D33,#REF!, "="&H$31) -> #REF!
D34: Content | E34: =COUNTIFS(Features[Area],"="&$D34,#REF!, "="&E$31) -> #REF! | F34: =COUNTIFS(Features[Area],"="&$D34,#REF!, "="&F$31) -> #REF! | G34: =COUNTIFS(Features[Area],"="&$D34,#REF!, "="&G$31) -> #REF! | H34: =COUNTIFS(Features[Area],"="&$D34,#REF!, "="&H$31) -> #REF!
D35: Home Page | E35: =COUNTIFS(Features[Area],"="&$D35,#REF!, "="&E$31) -> #REF! | F35: =COUNTIFS(Features[Area],"="&$D35,#REF!, "="&F$31) -> #REF! | G35: =COUNTIFS(Features[Area],"="&$D35,#REF!, "="&G$31) -> #REF! | H35: =COUNTIFS(Features[Area],"="&$D35,#REF!, "="&H$31) -> #REF!
D36: Administration | E36: =COUNTIFS(Features[Area],"="&$D36,#REF!, "="&E$31) -> #REF! | F36: =COUNTIFS(Features[Area],"="&$D36,#REF!, "="&F$31) -> #REF! | G36: =COUNTIFS(Features[Area],"="&$D36,#REF!, "="&G$31) -> #REF! | H36: =COUNTIFS(Features[Area],"="&$D36,#REF!, "="&H$31) -> #REF!
E37: =COUNTIFS(Features[Area],"="&$D37,#REF!, "="&E$31) -> #REF! | F37: =COUNTIFS(Features[Area],"="&$D37,#REF!, "="&F$31) -> #REF! | G37: =COUNTIFS(Features[Area],"="&$D37,#REF!, "="&G$31) -> #REF! | H37: =COUNTIFS(Features[Area],"="&$D37,#REF!, "="&H$31) -> #REF!
E38: =COUNTIFS(Features[Area],"="&$D38,#REF!, "="&E$31) -> #REF! | F38: =COUNTIFS(Features[Area],"="&$D38,#REF!, "="&F$31) -> #REF! | G38: =COUNTIFS(Features[Area],"="&$D38,#REF!, "="&G$31) -> #REF! | H38: =COUNTIFS(Features[Area],"="&$D38,#REF!, "="&H$31) -> #REF!
E39: =COUNTIFS(Features[Area],"="&$D39,#REF!, "="&E$31) -> #REF! | F39: =COUNTIFS(Features[Area],"="&$D39,#REF!, "="&F$31) -> #REF! | G39: =COUNTIFS(Features[Area],"="&$D39,#REF!, "="&G$31) -> #REF! | H39: =COUNTIFS(Features[Area],"="&$D39,#REF!, "="&H$31) -> #REF!
E40: =COUNTIFS(Features[Area],"="&$D40,#REF!, "="&E$31) -> #REF! | F40: =COUNTIFS(Features[Area],"="&$D40,#REF!, "="&F$31) -> #REF! | G40: =COUNTIFS(Features[Area],"="&$D40,#REF!, "="&G$31) -> #REF! | H40: =COUNTIFS(Features[Area],"="&$D40,#REF!, "="&H$31) -> #REF!
C42: Features Validation | D42: =SUM(E42:G42) -> #REF! | E42: =COUNTIF(#REF!,"="&E43) -> #REF! | F42: =COUNTIF(#REF!,"="&F43) -> #REF! | G42: =COUNTIF(#REF!,"="&G43) -> #REF!
D43: Total | E43: Pending | F43: Validating | G43: Approved
C44: by Area | E44: =SUM(E45:E52) -> #REF! | F44: =SUM(F45:F52) -> #REF! | G44: =SUM(G45:G52) -> #REF!
D45: Navigation | E45: =COUNTIFS(Features[Area],"="&$D45,#REF!, "="&E$43) -> #REF! | F45: =COUNTIFS(Features[Area],"="&$D45,#REF!, "="&F$43) -> #REF! | G45: =COUNTIFS(Features[Area],"="&$D45,#REF!, "="&G$43) -> #REF!
D46: Content | E46: =COUNTIFS(Features[Area],"="&$D46,#REF!, "="&E$31) -> #REF! | F46: =COUNTIFS(Features[Area],"="&$D46,#REF!, "="&F$31) -> #REF! | G46: =COUNTIFS(Features[Area],"="&$D46,#REF!, "="&G$31) -> #REF!
D47: Home Page | E47: =COUNTIFS(Features[Area],"="&$D47,#REF!, "="&E$31) -> #REF! | F47: =COUNTIFS(Features[Area],"="&$D47,#REF!, "="&F$31) -> #REF! | G47: =COUNTIFS(Features[Area],"="&$D47,#REF!, "="&G$31) -> #REF!
D48: Administration | E48: =COUNTIFS(Features[Area],"="&$D48,#REF!, "="&E$31) -> #REF! | F48: =COUNTIFS(Features[Area],"="&$D48,#REF!, "="&F$31) -> #REF! | G48: =COUNTIFS(Features[Area],"="&$D48,#REF!, "="&G$31) -> #REF!
...

Sheet Releases
B2: Solution Release List | E2: Release: versiones intermedias del proyecto que permitan una validación incremental del avance de las funcionalidades implementadas en la solución según acordado entre PM, CF, ARQ y Cliente
C5: Proyecto | D5: =Summary!D4 -> Portal Agentes | F5: Versión | G5: 1.0
C6: Owner | D6: =Summary!D5 -> Alex Olivé | F6: Fecha
B9: Id | C9: Release | D9: Release Name | E9: Description | F9: Feat. Included | G9: Feat. Validated | H9: Delivery Date | I9: Status
B10: RD.01 | C10: Design Close | D10: Cierre Diseño Funcional | E10: Finalización del diseño y concreción de Requerimientos y Funcionalidades de la solución para determinar el plan de trabajo según las Releases previstas. | F10: =COUNTIFS(#REF!,"="&$C10,#REF!,"=Included") -> #REF! | G10: =COUNTIFS(#REF!,"="&$C10,#REF!,"=Approved") -> #REF! | H10: 45717 | I10: Planned
B11: RL.01 | C11: Beta 1 | D11: Intranet: Home y navegación | F11: =COUNTIFS(#REF!,"="&$C11,#REF!,"=Included") -> #REF! | G11: =COUNTIFS(#REF!,"="&$C11,#REF!,"=Approved") -> #REF! | H11: 45748 | I11: Finished
B12: RL.02 | C12: Beta 2 | D12: Board de Comunicación | F12: =COUNTIFS(#REF!,"="&$C12,#REF!,"=Included") -> #REF! | G12: =COUNTIFS(#REF!,"="&$C12,#REF!,"=Approved") -> #REF! | H12: 45778 | I12: Planned
B13: RL.03 | C13: Beta 3 | D13: Boards Documentales | F13: =COUNTIFS(#REF!,"="&$C13,#REF!,"=Included") -> #REF! | G13: =COUNTIFS(#REF!,"="&$C13,#REF!,"=Approved") -> #REF! | H13: 45809 | I13: Planned
B14: RL.04 | C14: Go Live | D14: Entrega final | F14: =COUNTIFS(#REF!,"="&$C14,#REF!,"=Included") -> #REF! | G14: =COUNTIFS(#REF!,"="&$C14,#REF!,"=Approved") -> #REF! | H14: 45839 | I14: Planned

Sheet Requirements
B2: Project Requirement List | E2: Requerimientos: problemáticas y necesidades del cliente que deben ser resueltas por la solución a desarrollar, contemplando todas las preocupaciones, ideas y peticiones expuestas durante el análisis.
C4: Proyecto | D4: Portal Agentes | F4: Versión | G4: 3.0
C5: Owner | D5: =Summary!D5 -> Alex Olivé | F5: Fecha | G5: 45980
B8: Id | C8: Area | D8: Requirement | E8: Description | F8: Type | G8: Requester | H8: Priority | I8: Status | J8: Session | K8: Feature | L8: Comments
B9: RQ.01 | C9: Métodos Analíticos | D9: Carga de Documentos PDF Pre-digitalizados | E9: Cuando el usuario autorizado accede al Agente de Métodos Analíticos desde cualquiera de los canales habilitados (portal web, Microsoft Teams o weConnect) y selecciona la opción de procesar documento, el sistema debe permitir la carga de archivos de métodos analíticos químicos procedentes de hasta 100 clientes distintos con formatos documentales variables. El sistema debe validar que el formato del archivo cargado es compatible con los tipos soportados (¿PDF, Word? → Definir en Discovery) y que el tamaño no excede los 200MB establecidos como límite. Una vez validado el archivo, la carga se integra automáticamente con Azure AI Document Intelligence para el posterior procesamiento estructurado del documento. Los documentos procesados corresponden a métodos analíticos químicos que contienen información técnica estructurada en apartados específicos (objetivo, reactivos, equipamiento, condiciones cromatográficas, preparación de muestras, secuencia de inyección, sistema de idoneidad y cálculos). | F9: User | H9: Must have | I9: Pending | L9: Accesible desde 3 canales: Portal web, MS Teams y weconnect.
B10: RQ.02A | C10: Métodos Analíticos | D10: Extracción Estructura 8 Apartados (PoC Validado) | E10: Cuando el usuario carga un documento de método analítico químico y solicita procesarlo, el sistema extrae la información organizada en 8 apartados especializados. Esta estructura fue validada en el PoC realizado por Esteve con Tokiota. Apartados a extraer: - AIM - Objetivo del método - REAGENTS - Reactivos y calidades - EQUIPMENT - Instrumentos utilizados - CHROMATOGRAPHIC CONDITIONS - Fases móviles y condiciones - SAMPLE AND STANDARD PREPARATION - Preparación de muestras - INJECTION SEQUENCE - Secuencia de inyecciones - SYSTEM SUITABILITY - Parámetros de idoneidad - CALCULATIONS - Criterios de cálculo El sistema utilizará prompts especializados validados en el PoC que alcanzaron tasas de éxito del 93.5% con GPT-4o y 98.4% con Phi-4 sobre documentos reales de múltiples proveedores. | F10: Technology | H10: Must have | I10: Pending
B11: RQ.02B | C11: Métodos Analíticos | D11: Manejo de Apartados con Resultados Variables | E11: Cuando el sistema completa la extracción de los 8 apartados (RQ.02A), el usuario visualiza los resultados obtenidos. El sistema replica el proceso validado en el PoC de ESTEVE utilizando los prompts predefinidos. Los resultados pueden variar según la estructura y formato del documento origen de cada cliente. El usuario revisa los apartados extraídos. Si detecta información que requiere ajuste, puede continuar la conversación con el agente para refinar el resultado (ver RQ.07). Comments (contexto técnico interno): PoC Tokiota identificó variabilidad en ciertos apartados: - REAGENTS: posible redundancia en algunos documentos - EQUIPMENT: formatos variables según proveedor TBD Marc/Eduard: criterios de comportamiento esperado en estos casos. | F11: User | H11: Must have | I11: Pending | L11: PoC identificó 2 apartados problemáticos: REAGENTS (redundancia) EQUIPMENT (formatos).
B12: RQ.03 | C12: Métodos Analíticos | D12: Generación de Output Estructurado con Preservación de Formato | E12: Cuando el usuario solicita procesar un documento de método analítico, el sistema extrae la información de los 8 apartados y genera un documento de salida en formato texto plano (.txt) con estructura enriquecida. Estructura del documento generado: - Cabeceras jerárquicas por apartado (AIM, REAGENTS, EQUIPMENT, etc.) - Fórmulas químicas como texto (ejemplo: H₂O) - Información tabular representada mediante texto estructurado con separadores claros - Secciones y sub-secciones indicadas mediante cabeceras El usuario descarga el documento generado desde la interfaz conversacional TBDs Discovery: - Validar con 3-5 samples reales si formato texto plano cumple expectativas usuario - Si cliente requiere formato avanzado (tablas preservadas), evaluar cambio a DOCX (fuera alcance propuesta actual) | F12: User | H12: Must have | I12: Pending | L12: Según propuesta página 13, el agente genera documento con formato de texto plano. Formato específico TBD en Discovery. El documento generado debe ser descargable por el usuario. La conversión se realiza utilizando los prompts predefinidos por Esteve validados en su POC previo.
B13: RQ.04 | C13: Métodos Analíticos | D13: Procesamiento de Múltiples Ficheros con Modelo Pay-Per-Use | E13: Cuando el usuario carga múltiples documentos de métodos analíticos, el sistema procesa cada documento de forma escalable sin límites de volumen operativo. El sistema soporta hasta 100 variaciones de formato documental de diferentes clientes (tipos de documento entrenados en el modelo). Tecnologías: - Azure AI Document Intelligence (OCR y procesamiento) - Azure AI Foundry (extracción con prompts especializados) El consumo de recursos se factura según uso real (modelo pay-per-use). El usuario con rol Administrador monitoriza el consumo y presupuesto en tiempo real desde el dashboard de consumos (RQ.27). | F13: Infraestructure | H13: Must have | I13: Pending
B14: RQ.05 | C14: Métodos Analíticos | D14: Control de Acceso Restringido y Auditoría Completa | E14: Cuando un usuario accede al Portal, el sistema muestra únicamente los agentes para los que está autorizado según su pertenencia a grupos de Active Directory. El agente Métodos Analíticos es visible solo para usuarios del grupo AD autorizado. Auditoría de operaciones: El sistema registra automáticamente cada operación de procesamiento con los siguientes campos: - Usuario que ejecutó la operación - Fecha y hora (timestamp) - Canal de acceso (Portal web / Teams / weConnect) - Agente utilizado - Documento de entrada procesado - Documento de salida generado - Resultado de la operación (éxito / error) El Administrador accede a los registros de auditoría desde el dashboard de gobernanza (ver RQ.27). TBD Discovery: - Grupo AD específico para acceso a Métodos Analíticos | F14: Business | H14: Must have | I14: Pending
B15: RQ.06 | C15: Métodos Analíticos | D15: Pantalla Supervisión Métodos Analíticos | E15: Cuando un usuario con rol Administrador o usuario autorizado de supervisión del área de Métodos Analíticos accede a la pantalla de supervisión del Agente, el sistema muestra el listado de conversaciones realizadas con el agente. Información del listado: - Usuario que ejecutó la conversación - Fecha y hora - Documento procesado - Estado del resultado (completado / en curso / con errores) Al seleccionar una conversación, el sistema visualiza: - Historial completo de intercambios (consulta usuario → respuesta agente) - Documento base procesado (con opción de descarga) - Resultados de extracción generados Filtros disponibles: rango de fechas, usuario, documento procesado, estado del resultado. Funcionalidad complementaria: El supervisor puede exportar el listado filtrado para análisis offline. Esta pantalla permite supervisión operativa y optimización iterativa del agente. Complementa la auditoría de operaciones del RQ.05. TBD Discovery: - Rol/grupo AD específico para supervisión de Métodos Analíticos - Formato de exportación (CSV, Excel) | F15: User | H15: Must have | I15: Pending
B16: RQ.07 | C16: Métodos Analíticos | D16: Refinamiento Iterativo de Resultados con el Agente | E16: Cuando el agente genera el resultado inicial estructurado en los 8 apartados, el usuario puede continuar la conversación para refinar el resultado mediante lenguaje natural, sin necesidad de re-procesar el documento completo. El sistema mantiene el contexto conversacional completo: - Documento original procesado - Extracciones previas por apartado - Refinamientos realizados en la sesión Esto permite ajustes iterativos como: corregir apartados específicos, resolver redundancias (ej. REAGENTS) o normalizar formatos variables (ej. EQUIPMENT). Al finalizar los ajustes, el usuario descarga el documento actualizado (ver RQ.03). Nota: Los apartados REAGENTS y EQUIPMENT presentaron mayor variabilidad en el PoC; el refinamiento conversacional mitiga estos casos. | F16: User | H16: Could have | I16: Pending
E17: PORTAL Y ACCESO (5 RQs)
B18: RQ.08 | C18: Acceso y Seguridad | D18: Acceso sin credenciales adicionales | E18: Cuando un empleado de Esteve accede al Portal de Agentes IA desde cualquier canal (Microsoft Teams o weConnect), el sistema debe permitir el acceso sin solicitar credenciales adicionales, aprovechando la autenticación única (SSO) con Microsoft Entra ID ya configurada en el entorno corporativo. El sistema debe reconocer automáticamente la identidad del usuario mediante su sesión activa de Microsoft 365, eliminando la necesidad de introducir usuario y contraseña adicionales. El acceso debe integrarse con las políticas de seguridad empresariales existentes, incluyendo autenticación multifactor (MFA) si está configurada por Esteve y políticas de acceso condicional (Conditional Access) para garantizar que solo dispositivos corporativos gestionados o dispositivos que cumplan con las políticas de compliance pueden acceder al portal. Esto proporciona una experiencia de usuario sin fricciones manteniendo los estándares de seguridad empresariales. | F18: Infraestructure | H18: Must have | I18: Pending
B19: RQ.09 | C19: Acceso y Seguridad | D19: Integración con Microsoft Teams y weConnect | E19: Cuando un empleado de Esteve necesita acceder al Portal de Agentes IA, el sistema debe estar disponible mediante dos canales principales de acceso corporativo: la aplicación de Microsoft Teams y la intranet corporativa weConnect. Cuando el usuario accede desde Microsoft Teams, el sistema debe integrarse como aplicación nativa de Teams, aprovechando la sesión activa de Microsoft 365 del usuario sin solicitar credenciales adicionales (ver RQ.10). EL usuario localiza el portal mediante búsqueda de aplicaciones o mediante el catálogo de aplicaciones de Teams. Cuando el usuario accede desde weConnect (intranet corporativa de Esteve), el sistema debe integrarse mediante iframe embebido o enlace directo, manteniendo igualmente la sesión SSO de Microsoft 365 sin requerir autenticación adicional. Ambos canales proporcionan experiencia de usuario equivalente en funcionalidades core (acceso agentes, historial conversaciones, favoritos), aunque la interfaz se adapta al contenedor (ventana Teams vs navegador weConnect). | F19: Technology | H19: Must have | I19: Pending
B20: RQ.10 | C20: Acceso y Seguridad | D20: Sistema de roles con permisos diferenciados | E20: Cuando el sistema valida la identidad de un usuario autenticado, el sistema debe asignar automáticamente uno de tres roles funcionales según su pertenencia a grupos de Active Directory. Cuando un usuario tiene rol de Usuario, el sistema debe permitir usar agentes disponibles según audiencias asignadas, consultar historial conversaciones propias, guardar prompts personales y marcar favoritos. Cuando un usuario tiene rol de Gestor Agentes, el sistema debe habilitar además la creación de agentes contextuales mediante wizard autónomo, publicación/despublicación de agentes creados, configuración de audiencias (grupos AD) para agentes propios, y gestión de hasta 3 bibliotecas SharePoint como contextos. Cuando un usuario tiene rol de Administrador, el sistema debe proporcionar control total de la plataforma incluyendo dashboards consumos/uso, configuración alertas presupuestarias, gestión centralizada de todos los agentes (edición, desactivación), y acceso completo a logs auditoría. | F20: Business | H20: Must have | I20: Pending
B21: RQ.11 | C21: Navegación y UX | D21: Navegación y búsqueda de agentes en el portal | E21: Cuando un usuario accede al Portal de Agentes IA desde Microsoft Teams o desde la intranet corporativa weconnect, el sistema debe mostrar únicamente los agentes a los que tiene acceso según su pertenencia a grupos de Active Directory definidos como audiencias. El sistema permite búsqueda activa de agentes por nombre y descripción, facilitando la localización rápida en catálogos extensos. El sistema permite ordenar el listado de agentes disponibles según diferentes criterios: - Alfabético (A-Z, Z-A) - Por uso reciente del usuario - Por popularidad (agentes más utilizados globalmente) Por defecto, el catálogo muestra los agentes ordenados alfabéticamente. El usuario selecciona el criterio de ordenación desde un selector visible en la cabecera del listado. Cuando el usuario identifica agentes de uso frecuente, el sistema permite marcarlos como favoritos para acceso rápido posterior. El sistema proporciona acceso al historial completo de conversaciones personalizado de cada usuario, organizado cronológicamente y vinculado al agente correspondiente. | F21: User | H21: Must have | I21: Pending | L21: TBD Discovery: - Grupos Active Directory específicos por audiencia (ej: RD-Reactivos, IT-Administradores, All-Employees) - Límite favoritos por usuario (¿ilimitados o máximo razonable?)
B22: RQ.12 | C22: Navegación y UX | D22: Ficha de Agente: Metadatos y Categorización | E22: Cuando el sistema muestre un agente en el catálogo del Portal, debe presentar información básica que facilite su comprensión y uso por parte del usuario. La información básica a mostrar incluye: - Nombre del agente - Propietario (para agentes contextuales creados por Gestores) - Tipología - Descripción funcional - Contexto asociado (si aplica) - Modelo utilizado Esta información es administrada mediante el Gestor de Agentes para agentes contextuales (RQ.23), y predefinida por IT para agentes genéricos y especializados. El diseño visual del catálogo debe integrarse con la estética corporativa de weConnect en los aspectos básicos de la UI. | F22: User | H22: Must have | I22: Pending
B23: RQ.13 | C23: Acceso y Seguridad | D23: Soporte multiidioma | E23: Cuando un usuario accede al Portal de Agentes IA, el sistema debe permitir seleccionar el idioma de la interfaz de usuario entre 6 idiomas: - Español (ES) - Inglés (EN) - Alemán (DE) - Chino (ZH) - Portugués (PT) - Francés (FR). Cuando el usuario selecciona un idioma, el sistema debe aplicar la traducción a todos los elementos de interfaz: menús de navegación, botones, etiquetas de campos, mensajes de error, tooltips, y textos estáticos del portal. El sistema debe persistir la preferencia de idioma del usuario entre sesiones, almacenándola en su perfil de usuario. Si el usuario no ha seleccionado idioma previamente, el sistema debe aplicar el idioma default configurado por el Administrador (típicamente español para Esteve España). | F23: User | H23: Must have | I23: Pending
E24: AGENTES IA (7 RQs)
B25: RQ.14 | C25: Agentes IA | D25: Comportamiento base compartido por agentes genéricos | E25: Cuando un usuario interactúa con cualquiera de los 10 agentes genéricos del portal, el sistema proporciona capacidades conversacionales multiturno en lenguaje natural. El agente responde en el idioma de la consulta del usuario. El sistema selecciona modelo según especialización del agente: - 9 agentes generalistas (Consulta Abierta, Traducción, Redactor Corporativo, Consulta Documentos, Resumen Ejecutivo, Revisor Estilo, Preparación Reuniones, Generador URS, Redactor RFPs) - 1 agente especializado (Researcher para investigación avanzada) Los agentes genéricos operan SIN contexto corporativo empresarial, basando respuestas únicamente en capacidades del modelo de lenguaje. Esto los diferencia de agentes contextuales (RQ.21-26) que acceden a bibliotecas SharePoint específicas. Cuando el agente genera documentos como salida (ejemplo: Redactor Corporativo), el usuario puede descargarlos (RQ.17). Gestión de disponibilidad: Cuando el sistema experimenta alta demanda, muestra un mensaje informativo al usuario y permite reintentar la operación. El portal muestra un aviso visible indicando que las respuestas de IA son orientativas y requieren validación del usuario. TBDs Discovery: - Prompts sistema predefinidos por agente - Formato documentos salida (DOCX, .txt) - Ubicación del disclaimer de IA (footer, modal inicial) | F25: Technology | H25: Must have | I25: Pending | L25: TBD Discovery: - Prompts sistema predefinidos exactos para cada agente genérico - Formato entrega documentos salida (DOCX, PDF, Markdown)
B26: RQ.15 | C26: Agentes IA | D26: Provisión de 10 agentes genéricos preconfigurados | E26: Cuando se despliegue el Portal de Agentes IA en Release #3, el sistema debe incluir 10 agentes genéricos configurados para uso de los empleados Esteve (según audiencias definidas). Cada agente debe tener prompt del sistema específico validado y descripción funcional visible en catálogo portal. Agentes incluidos: 1. Consulta Abierta - generalista sin especialización 2. Traducción - tono corporativo profesional 3. Consulta Documentos - análisis hasta 3 documentos 4. Redactor Corporativo - correos, comunicados, informes 5. Resumen Ejecutivo - extracción bullets claros de textos largos 6. Revisor Estilo/Calidad - gramática, claridad y tono 7. Preparación Reuniones - agendas, puntos clave 8. Generador URS - User Requirements Specifications 9. Redactor RFPs - Request for Proposals estructurados Agente especializado: 10. Researcher - Investigación especializada avanzada TBDs Discovery: - Prompts sistema específicos por agente - Audiencias por defecto (¿todos empleados o segmentado?) | F26: Business | H26: Must have | I26: Pending | L26: Diferenciación modelos: 9 agentes usan GPT-4o-mini (económico, suficiente tareas estándar). Solo Researcher usa GPT-4o (mayor capacidad investigación avanzada, mayor coste justificado por complejidad).
B27: RQ.16 | C27: Agentes IA | D27: Interacción conversacional con agentes IA | E27: El portal permite a los usuarios interactuar con los agentes mediante conversaciones en lenguaje natural. Cuando el usuario envía una consulta, el sistema: - Interpreta la consulta en lenguaje natural - Genera respuesta basada en el modelo del agente (RQ.14) - Muestra respuesta en formato conversacional - Mantiene contexto conversacional multiturno El sistema mantiene historial de conversaciones personalizado por usuario (persistido entre sesiones). El agente Consulta Documentos permite adjuntar hasta 3 archivos simultáneos en formatos: Word, PDF, TXT, Excel, PPT, JPG, GIF, PNG. Moderación de contenido: El sistema aplica filtros en consultas y respuestas según políticas corporativas. Si detecta contenido que incumple las políticas (lenguaje inapropiado, información sensible, términos bloqueados), bloquea o redacta el contenido e informa al usuario. TBDs Discovery: - Límites historial: número conversaciones, retención temporal - Gestión conversaciones: crear nueva, renombrar, eliminar, compartir - Categorías de contenido a filtrar y términos bloqueados (definir con Compliance Esteve) | F27: User | H27: Must have | I27: Pending | L27: TBD Discovery: - Límites historial: conversaciones por usuario, retención temporal - Memoria conversación: multiturno, referencias contextuales - Gestión conversaciones: crear nueva, recuperar previa, compartir
B28: RQ.17 | C28: Agentes IA | D28: Generación de documentos descargables como salida | E28: Cuando un agente genera contenido estructurado como resultado de la conversación, el sistema debe permitir al usuario descargar el resultado como documento. Los agentes que generan documentos según propuesta incluyen: - Redactor Corporativo - Generador URS - Redactor RFPs - Métodos Analíticos El formato de documento se definirá durante Discovery según tipo de agente. Para agente Métodos Analíticos, el formato será texto plano enriquecido según propuesta línea 159. Cuando el usuario completa la conversación, el sistema debe proporcionar opción de descarga del documento generado. TBDs Discovery: - Formato descarga por tipo agente (definir en Discovery) | F28: User | H28: Must have | I28: Pending | L28: TBD Discovery: - Formatos descarga: DOCX editable, PDF, otros - Preview antes descarga - Templates corporativos Esteve (logos, headers, footers) - Límites generación: tamaño máximo
B29: RQ.18 | C29: Agentes IA | D29: Selección de prompts predefinidos | E29: Cuando un usuario inicia una conversación con un agente, el sistema debe poner a disposición hasta 3 prompts predefinidos configurados para ese agente. El usuario puede seleccionar uno de estos prompts predefinidos o escribir consulta libre en lenguaje natural. Para agentes genéricos (10 preconfigurados), los prompts predefinidos serán configurados durante el despliegue. La definición específica de estos prompts se trabajará en sesiones Discovery con equipos Esteve. Para agentes contextuales (creados por Gestores vía wizard RQ-23), el sistema debe permitir configurar hasta 3 prompts predefinidos durante la creación del agente. Los prompts predefinidos son independientes de la biblioteca de prompts personales del usuario (RQ-22), donde cada usuario almacena y recupera sus propios prompts creados. TBDs Discovery: - Contenido específico prompts por agente genérico (sesiones colaborativas Esteve) - Mecanismo selección prompt por usuario (UX definir en Discovery) - Límites caracteres por prompt predefinido | F29: User | H29: Should have | I29: Pending
B30: RQ.19 | C30: Agentes IA | D30: Sistema de agentes favoritos | E30: Cuando un usuario identifica agentes de uso frecuente, el sistema debe permitir añadirlos a un listado personal de agentes favoritos para acceso rápido posterior. Cada usuario mantiene su propio listado de favoritos independiente de otros usuarios. El sistema debe persistir la lista de favoritos del usuario entre sesiones. Cuando el usuario accede al Portal, el sistema debe proporcionar acceso rápido a los agentes marcados como favoritos, facilitando inicio de conversación sin necesidad de buscar en catálogo completo. El sistema debe permitir añadir agentes a favoritos desde el catálogo y eliminar agentes de la lista de favoritos. TBDs Discovery: - Límite máximo favoritos por usuario - Mecanismo visualización favoritos (UX definir en sesiones) - Mecanismo añadir/eliminar favoritos (UX definir en sesiones) | F30: User | H30: Should have | I30: Pending | L30: TBD Discovery: - UX favoritos: sección destacada página principal, indicador visual catálogo - Persistencia: entre sesiones, entre canales (Teams/weconnect) - Límites: máximo favoritos por usuario Gestión: añadir, eliminar, ordenación
B31: RQ.20 | C31: Agentes IA | D31: Gestión de prompts personales | E31: Cuando un usuario utiliza un prompt en una conversación con un agente, el sistema debe permitir guardar ese prompt en una biblioteca personal de prompts para reutilización futura. Cada prompt guardado pertenece exclusivamente al usuario que lo creó. Solo el creador tiene acceso a sus prompts personales. Cuando el usuario guarda un prompt, el sistema debe almacenar: título del prompt, descripción del prompt, y texto completo del prompt. El prompt se guarda en el idioma en que fue escrito por el usuario (un idioma por prompt). El sistema debe permitir al usuario buscar en su biblioteca personal de prompts por descripción. Cuando el usuario desea reutilizar un prompt guardado, el sistema debe proporcionar mecanismo para copiar el prompt desde la biblioteca a una conversación activa con un agente. TBDs Discovery: - Límite máximo prompts por usuario - Mecanismo copia prompt a conversación (UX definir en sesiones) | F31: User | H31: Should have | I31: Pending | L31: TBD Discovery: - UX: mostrar junto prompts predefinidos galería visual, diferenciación - Gestión: editar, duplicar, eliminar - Límite máximo prompts por usuario - Organización: carpetas, etiquetas
E32: CITIZEN DEVELOPMENT (6 RQs)
B33: RQ.21 | C33: Citizen Development | D33: Creación y gestión de agentes contextuales | E33: Cuando un usuario con rol Gestor de Agentes accede a la herramienta de creación de agentes, el sistema proporciona un wizard autónomo para crear agentes contextuales sin intervención IT. Cuando el Gestor crea un agente contextual, el wizard solicita: - nombre del agente, descripción, audiencia (grupos Active Directory) - instrucciones (texto plano que predefine comportamiento) - modelo de IA a utilizar (seleccionable entre los habilitados por el Administrador) - hasta 3 prompts predefinidos (RQ.20) - hasta 3 bibliotecas SharePoint como contexto (RQ.24). El sistema permite al Gestor gestionar el ciclo de vida de sus agentes: publicar, despublicar, eliminar. La lista de agentes creados por el Gestor es accesible para administración. El sistema ejecuta un flujo Power Automate diario que identifica agentes creados en las últimas 24h e informa vía email al Administrador con: agentes generados, propietarios, audiencias, contextos. TBDs Discovery: - Catálogo de modelos Azure OpenAI habilitados para selección en wizard - Límites Gestor: máximo agentes creables, consumo tokens/mes | F33: User | H33: Must have | I33: Pending | L33: TBD Discovery: - Workflow aprobación: automático vs revisión manual Admin - Límites Gestor: máximo agentes, tokens/mes
B34: RQ.22 | C34: Citizen Development | D34: Configuración Contexto SharePoint | E34: Cuando un Gestor de Agentes crea un agente contextual mediante wizard (RQ.23), el sistema debe permitir seleccionar hasta 3 bibliotecas de SharePoint específicas que actuarán como contexto documental del agente. Los agentes contextuales se diferencian de los 10 agentes genéricos del portal en que los contextuales acceden a información corporativa específica de las bibliotecas SharePoint seleccionadas. El sistema debe aplicar límites por agente contextual: máximo 2000 ficheros o 5GB de contenido total, lo que se alcance primero. Los formatos de documento soportados son: Word, PDF, texto plano, Excel, PowerPoint, JPG, Git y PNG, con tamaño máximo de 200MB por fichero individual. Cuando un agente contextual alcanza los límites de 2000 ficheros o 5GB, el sistema debe generar alerta automática vía email al Gestor creador del agente, indicando necesidad de revisar contexto. TBDs Discovery: - Mecanismo selección bibliotecas bibliotecas SharePoint en wizard - Validación permisos Gestor sobre bibliotecas seleccionadas | F34: Business | H34: Must have | I34: Pending
B35: RQ.23 | C35: Citizen Development | D35: Indexación y Refresco Contexto | E35: Cuando un Gestor de Agentes configura contexto documental SharePoint (RQ.24), el sistema debe procesar e indexar el contenido de forma asíncrona, sin bloquear la finalización del wizard de creación del agente. El sistema debe implementar refresco automático del contexto con periodicidad parametrizable por el Administrador. La granularidad mínima de refresco es 1 vez al día según propuesta. El procesamiento del contexto documental permite consultas semánticas durante conversaciones con el agente contextual. El tiempo de procesamiento varía según volumen de documentación indexada. Cada agente contextual mantiene su contexto separado de otros agentes, evitando cruce de información entre agentes distintos. TBDs Discovery: - Opciones granularidad refresco disponibles (¿1 vez/día?) - ¿Indicadores progreso indexación visible a Gestor? | F35: Technology | H35: Must have | I35: Pending
B36: RQ.24 | C36: Citizen Development | D36: Gestión Ciclo Vida y Control Agentes | E36: Cuando un Gestor Agentes accede a la herramienta de gestión de agentes dentro del Portal, el sistema debe mostrar una lista de agentes creados por el usuario Gestor (y aquellos en los que otro usuario lo haya definido como Gestor) para su administración. El sistema debe permitir ejecutar acciones básicas del ciclo de vida sobre los agentes gestionados: Acciones Gestor: - Publicar: Hacer visible el agente a las audiencias definidas (grupos AD) - Despublicar: Ocultar temporalmente el agente sin eliminarlo - Eliminar: Borrar permanentemente el agente y su configuración Acciones Administrador: Cuando los administradores necesiten controlar consumo de recursos Azure OpenAI, el sistema debe permitir deshabilitar puntualmente ciertos agentes para limitar su uso, actuando sobre alertas de consumo recibidas. TBDs Discovery: - UX lista agentes: tabla, cards, filtros disponibles - Confirmación eliminación: modal, validación impacto usuarios activos - Log auditoría: registro acciones ciclo vida para compliance | F36: User | H36: Must have | I36: Pending
B37: RQ.25 | C37: Citizen Development | D37: Notificación Límites Contexto | E37: Cuando un agente contextual alcanza los límites máximos definidos por contexto, el sistema debe ejecutar dos acciones: Comportamiento sistema: 1. Detener indexación: Dejar de indexar nueva documentación de las bibliotecas SharePoint asociadas 2. Notificar owner: Enviar correo electrónico automático al propietario (owner) del agente informando del límite alcanzado La notificación permite al Gestor Agentes tomar decisiones sobre la gestión del contexto documental: revisar documentos indexados, eliminar contenido obsoleto, o solicitar ampliación de límites a Administrador si justificado. TBDs Discovery: - Contenido email: asunto, cuerpo, datos incluidos (agente, límite alcanzado) | F37: Business | H37: Should have | I37: Pending
B38: RQ.26 | C38: Citizen Development | D38: Email Diario Admin Agentes Creados | E38: Cuando se ejecuta el flujo programado de Power Automate una vez al día, el sistema debe enviar un email consolidado al Administrador de Agentes IA con un listado de todos los agentes creados en el entorno Citizen Development durante el período diario. El email debe incluir información de los agentes generados y usuarios involucrados, detallando la misma información que se ha cargado al momento de la creación del Agente. Este requirement implementa notificación diaria mediante Power Automate, permitiendo al Administrador supervisar la actividad de creación de agentes en el entorno Citizen Development. Tecnologías: Power Automate (flujo programado) TBDs Discovery: - Horario ejecución flujo diario (28:00 AM, fin día 23:00?) - Formato email: ¿tabla HTML, listado texto, archivo adjunto CSV? - Campos exactos email: nombre agente, propietario, audiencia, contexto, timestamp - Comportamiento si 0 agentes creados: ¿email vacío o sin envío? | F38: Business | H38: Must have | I38: Pending
E39: DASHBOARDS Y GOBERNANZA (3 RQs)
B40: RQ.27 | C40: Dashboards y Gobernanza | D40: Dashboard de Uso y Análisis de Adopción | E40: Cuando un administrador accede al dashboard de uso (Panel 2 del BI), el sistema debe mostrar métricas agregadas de adopción de la plataforma, complementando el dashboard de consumos (RQ.28 - Panel 1). El dashboard debe proporcionar visibilidad de: - Número de conversaciones agrupadas por agente (métricas agregadas) - Total de accesos y usuarios activos por día - Patrones de uso y popularidad de agentes El dashboard debe permitir análisis mediante filtros: - Temporal: Rango de fechas personalizado - Organizativo: Unidad organizativa según estructura Active Directory de Esteve (Site, Location, Area, Departamento) - Origen: SharePoint y Teams Diferenciación de paneles: - RQ.27 (Uso): Foco adopción (engagement, patrones uso, popularidad agentes) - RQ.28 (Consumos): Foco presupuestario (tokens, costes, alertas) Nota técnica: Ambos paneles (Consumos + Uso) forman parte de la misma solución BI con paneles/pantallas diferenciados. | F40: User | H40: Must have | I40: Pending
B41: RQ.28 | C41: Dashboards y Gobernanza | D41: Dashboard de consumos de tokens y costes | E41: Cuando un usuario con rol Administrador accede al dashboard de consumos del portal, el sistema debe mostrar métricas detalladas para control presupuestario del modelo pay-per-use escalable. El dashboard debe proporcionar visibilidad de: - Consumo de tokens de entrada y salida agrupado por agente individual - Consumo en € agrupado por agente - Consumo por persona El dashboard debe permitir análisis mediante filtros: - Temporal: Rango de fechas personalizado - Organizativo: Unidad organizativa según estructura Active Directory de Esteve (Site, Location, Area, Departamento) - Origen: SharePoint y Teams Separación Entornos: La propuesta especifica 2 recursos Azure AI Foundry distintos (Citizen Development + Métodos Analíticos). El dashboard debe permitir separar costes por entorno para presupuestos independientes. | F41: User | H41: Must have | I41: Pending
B42: RQ.29 | C42: Dashboards y Gobernanza | D42: Alertas de Consumo Azure AI Foundry | E42: Cuando el consumo de servicios Azure OpenAI alcance los límites configurados por Esteve, el sistema debe enviar alertas automáticas vía correo electrónico a los administradores del sistema utilizando alertas nativas de Azure Al Foundry no desarrolladas por Raona. Cuando los administradores reciban una alerta de consumo, deben poder actuar en consecuencia, por ejemplo limitando el uso de ciertos agentes mediante su deshabilitación puntual. El sistema debe generar alertas diferenciadas: una para los agentes del entorno Citizen Development y otra para el entorno Métodos Analíticos. TBD Discovery: Límites específicos por entorno (tokens/mes, €/mes, ambos) Umbrales alertas (50%, 80%, 100% del límite) Frecuencia verificación consumo (tiempo real, diaria, horaria) | F42: Infraestructure | H42: Must have | I42: Pending
B43: RQ.30 | C43: Dashboards y Gobernanza | D43: Integración Purview Etiquetas Sensibilidad | E43: Si Esteve tiene implementado Microsoft Purview como solución de etiquetado de información sensible, el sistema debe permitir activar un control adicional en la ingesta de contextos documentales. Cuando este control esté activado y el sistema procese documentos para indexación (RQ. 25 indexación y refresco contexto), debe vetar automáticamente documentos con ciertas etiquetas de sensibilidad configuradas (por ejemplo, "Confidencial") para que no formen parte de los contextos de agentes. Esta funcionalidad es CONDICIONAL: solo aplica si Esteve ya utiliza Purview activamente para clasificar documentos. La integración evita que información especialmente sensible alimente a la IA por error y se integra con el gobierno del dato existente. Tecnologías: Microsoft Purview (si implementado por Esteve) TBDs Discovery: - Esteve tiene Purview implementado: ¿sí/no? - Etiquetas sensibilidad a vetar: lista configurada por Admin - Comportamiento veto: bloqueo silencioso vs notificación Gestor agente | F43: Technology | H43: Could have | I43: Pending
B44: RQ.32
...

Sheet Features
B2: Solution Feature List | F2: Funcionalidades: características concretas de la solución final para que el equipo de desarrollo pueda implementarla adecuadamente y poder validarla mediante UATs con los interlocutores del cliente.
C4: Proyecto | D4: =Summary!D4 -> Portal Agentes | G4: Versión | H4: Final
C5: Owner | D5: =Summary!D5 -> Alex Olivé | G5: Fecha | H5: 46037
B7: Id | C7: Area | D7: Feature | E7: User Story | F7: Description | G7: Component | H7: Comments
B8: FT.01 | C8: Agente Métodos Analíticos | D8: Desarrollo Agente Especializado | E8: Carga de Documentos PDF Pre-digitalizados | F8: Cuando el usuario autorizado accede al Agente Métodos Analíticos desde cualquiera de los canales habilitados (Microsoft Teams o weConnect) y selecciona la opción de procesar documento, el sistema permite la carga de archivos de métodos analíticos químicos procedentes en hasta 100 variaciones de formato distintas. El sistema valida que el formato del archivo cargado es compatible con el tipo soportado (PDF) y que el tamaño no excede límites (aplica el límite de 200MB de agentes contextuales). Una vez validado el archivo, la carga se integra automáticamente con Azure AI Document Intelligence para el posterior procesamiento estructurado del documento. Los documentos procesados corresponden a métodos analíticos químicos que contienen información técnica estructurada en apartados específicos (objetivo, reactivos, equipamiento, condiciones cromatográficas, preparación de muestras, secuencia de inyección, sistema de idoneidad y cálculos). | G8: Agentes
B9: FT.02 | C9: Agente Métodos Analíticos | D9: PoC análisis prompting + pruebas | E9: Extracción Estructura 8 Apartados (PoC Validado) | F9: Cuando el usuario carga un documento de método analítico químico y solicita procesarlo, el sistema extrae la información organizada en 8 apartados especializados. Esta estructura fue validada en el PoC realizado por Esteve con Tokiota. Apartados a extraer: - AIM - Objetivo del método - REAGENTS - Reactivos y calidades - EQUIPMENT - Instrumentos utilizados - CHROMATOGRAPHIC CONDITIONS - Fases móviles y condiciones - SAMPLE AND STANDARD PREPARATION - Preparación de muestras - INJECTION SEQUENCE - Secuencia de inyecciones - SYSTEM SUITABILITY - Parámetros de idoneidad - CALCULATIONS - Criterios de cálculo El sistema utiliza prompts especializados validados en el PoC que alcanzaron tasas de éxito del 93.5% con GPT-4o y 98.4% con Phi-4 sobre documentos reales de múltiples proveedores. (Se producirá reevaluación para confirmar tasa de éxito) | G9: Agentes
B10: FT.02B | C10: Agente Métodos Analíticos | D10: PoC análisis prompting + pruebas | E10: Manejo de Apartados con Resultados Variables | F10: Cuando el sistema completa la extracción de los 8 apartados (FT.02), el usuario visualiza los resultados obtenidos. El sistema replica el proceso validado en el PoC de ESTEVE utilizando los prompts predefinidos. Los resultados pueden variar según la estructura y formato del documento origen de cada cliente. El usuario revisa los apartados extraídos. Si detecta información que requiere ajuste, el sistema ofrece mecanismos para corregirlo (ver FT.07). Comments (contexto técnico interno): PoC Tokiota identificó variabilidad en ciertos apartados: - REAGENTS: posible redundancia en algunos documentos - EQUIPMENT: formatos variables según proveedor | G10: Agentes
B11: FT.03 | C11: Agente Métodos Analíticos | D11: Desarrollo Agente Especializado | E11: Generación de Output Estructurado | F11: Cuando el usuario solicita procesar un documento de método analítico, el sistema extrae la información de los 8 apartados y genera un documento de salida en formato texto plano con estructura enriquecida basada en los resultados de PoC Tokiota. Estructura del documento generado: - Cabeceras jerárquicas por apartado (AIM, REAGENTS, EQUIPMENT, etc.) - Fórmulas químicas como texto (ejemplo: H₂O) - Secciones y sub-secciones indicadas mediante cabeceras El usuario descarga el documento generado desde la interfaz conversacional TBD Discovery: ¿documentos de método analítico de ejemplo para realizar pruebas? | G11: Agentes
B12: FT.04 | C12: Agente Métodos Analíticos | D12: Desarrollo Agente Especializado | E12: Procesamiento de Múltiples Ficheros | F12: Cuando el usuario carga múltiples documentos de métodos analíticos, el sistema procesa cada documento de forma escalable. El sistema soporta hasta 100 variaciones de formato documental de diferentes clientes (tipos de documento entrenados en el modelo). Tecnologías: - Azure AI Document Intelligence (OCR y procesamiento) - Azure AI Foundry (extracción con prompts especializados) El consumo de recursos se factura según uso real (modelo pay-per-use). El usuario con rol Administrador monitoriza el consumo y presupuesto en tiempo real desde el dashboard de consumos (FT.28). | G12: Agentes
B13: FT.05 | C13: Agente Métodos Analíticos | D13: Desarrollo Agente Especializado | E13: Control de Acceso Restringido | F13: Cuando un usuario accede al Portal, el sistema muestra únicamente los agentes para los que está autorizado según su pertenencia a grupos de Active Directory. El Agente Métodos Analíticos es visible solo para usuarios del grupo AD autorizado. TBD Discovery: - Grupo AD específico para acceso al Agente Métodos Analíticos | G13: Agentes
B14: FT.06 | C14: Agente Métodos Analíticos | D14: Desarrollo Visor de interacciones | E14: Pantalla Supervisión Agente Métodos Analíticos | F14: Cuando un usuario con rol Administrador Funcional o supervisor autorizado del área del Agente Métodos Analíticos accede a la pantalla de supervisión del Agente, el sistema muestra el listado de conversaciones realizadas con el agente. Información del listado: - Usuario que ejecutó la conversación - Fecha y hora - Documento procesado Al seleccionar una conversación, el sistema muestra: - Historial completo de intercambios (consulta usuario → respuesta agente) - Documento base procesado (con opción de descarga) - Resultados de extracción generados (output) Filtros disponibles: rango de fechas, usuario, documento procesado. TBD Discovery: - Rol/grupo AD específico para supervisión del Agente Métodos Analíticos | G14: Agentes | H14: [ESTEVE]: Creación grupo AD con únicamente este grupo
B15: FT.07 | C15: Agente Métodos Analíticos | D15: Desarrollo Agente Especializado | E15: Refinamiento Iterativo de Resultados con el Agente | F15: Cuando el agente genera el resultado inicial estructurado en los 8 apartados, el usuario puede continuar la conversación para refinar el resultado mediante lenguaje natural, sin necesidad de re-procesar el documento completo. El sistema mantiene el contexto conversacional: - Documento original procesado - Refinamientos realizados Esto permite ajustes como: corregir información de un apartado específico, eliminar redundancias o normalizar formatos variables (Ver FT.02B) Al finalizar los ajustes, el usuario descarga el documento actualizado (ver FT.03). | G15: Agentes
B16: FT.08 | C16: Acceso y Seguridad | D16: Configuración Portal de Agentes IA | E16: Acceso sin credenciales adicionales | F16: Cuando un empleado de Esteve accede al Portal de Agentes IA desde cualquier canal (Microsoft Teams o weConnect), el sistema permite el acceso sin solicitar credenciales adicionales, aprovechando la autenticación única (SSO) con Microsoft Entra ID ya configurada en el entorno corporativo. El sistema reconoce automáticamente la identidad del usuario mediante su sesión activa de Microsoft 365, eliminando la necesidad de introducir usuario y contraseña adicionales. El acceso se integra con las políticas de seguridad empresariales existentes. Esto proporciona una experiencia de usuario sin fricciones manteniendo los estándares de seguridad empresariales. | G16: Portal
B17: FT.09 | C17: Acceso y Seguridad | D17: Configuración Portal de Agentes IA | E17: Integración con Microsoft Teams y weConnect | F17: Cuando un empleado de Esteve necesita acceder al Portal de Agentes IA, el sistema está disponible mediante dos canales principales de acceso corporativo: la aplicación de Microsoft Teams y la intranet corporativa weConnect. Cuando el usuario accede desde Microsoft Teams, el sistema se integra como aplicación nativa de Teams, aprovechando la sesión activa de Microsoft 365 del usuario sin solicitar credenciales adicionales (ver FT.08). El usuario localiza el portal mediante búsqueda de aplicaciones o mediante el catálogo de aplicaciones de Teams. Cuando el usuario accede desde weConnect (intranet corporativa de Esteve), el sistema se integra mediante iframe embebido o enlace directo, manteniendo igualmente la sesión SSO de Microsoft 365 sin requerir autenticación adicional. Ambos canales proporcionan experiencia de usuario equivalente en funcionalidades core (acceso agentes, historial conversaciones, favoritos), aunque la interfaz se adapta al contenedor (ventana Teams vs navegador weConnect). | G17: Portal
B18: FT.10 | C18: Acceso y Seguridad | D18: Configuración Portal de Agentes IA | E18: Sistema de roles con permisos diferenciados | F18: Cuando el sistema valida la identidad de un usuario autenticado, el sistema detecta automáticamente uno de tres roles funcionales según su pertenencia a grupos de Active Directory. Cuando un usuario tiene rol de User, el sistema permite usar agentes disponibles según audiencias asignadas, consultar historial conversaciones propias, guardar prompts personales y marcar favoritos. Cuando un usuario tiene rol de Gestor Agentes, el sistema habilita además la creación de agentes contextuales mediante wizard autónomo, publicación/despublicación de agentes creados, configuración de audiencias (grupos AD) para agentes propios, y gestión de hasta 3 bibliotecas SharePoint como contextos por agente. Cuando un usuario tiene rol de Administrador, el sistema proporciona control total de la plataforma incluyendo dashboards consumos/uso, configuración alertas presupuestarias, gestión centralizada de todos los agentes (edición, desactivación), y acceso completo a logs auditoría. | G18: Portal
B19: FT.11 | C19: Navegación y UX | D19: Configuración Portal de Agentes IA | E19: Navegación y búsqueda de agentes en el portal | F19: Cuando un usuario accede al Portal de Agentes IA desde Microsoft Teams o desde la intranet corporativa weconnect, el sistema muestra únicamente los agentes a los que tiene acceso según su pertenencia a grupos de Active Directory definidos como audiencias. El sistema permite búsqueda activa de agentes por nombre, facilitando la localización rápida en catálogos extensos. Por defecto, el catálogo muestra los agentes ordenados alfabéticamente. El usuario selecciona el criterio de ordenación desde un selector visible en la cabecera del listado. Cuando el usuario identifica agentes de uso frecuente, el sistema permite marcarlos como favoritos para acceso rápido posterior. El sistema proporciona acceso al historial completo de conversaciones personalizado de cada usuario, organizado cronológicamente y vinculado al agente correspondiente. | G19: Portal
B20: FT.12 | C20: Navegación y UX | D20: Configuración Portal de Agentes IA | E20: Ficha de Agente: Metadatos y Categorización | F20: Cuando el sistema muestra un agente en el catálogo del Portal, presenta información básica que facilita su comprensión y uso por parte del usuario. La información básica a mostrar incluye: - Nombre del agente - Tipología - Descripción funcional - Contexto asociado (si aplica) - Modelo utilizado Esta información es administrada mediante el Gestor de Agentes para agentes contextuales (FT.21), y predefinida por IT para agentes genéricos y especializados. El diseño visual del catálogo se integra con la estética corporativa de weConnect en los aspectos básicos de la UI. | G20: Portal
B21: FT.13 | C21: Acceso y Seguridad | D21: Configuración Portal de Agentes IA | E21: Soporte multiidioma | F21: Cuando un usuario accede al Portal de Agentes IA, el sistema detecta automáticamente el idioma por defecto del usuario. La solución soporta los siguientes idiomas: - Español (ES) - Inglés (EN) - Alemán (DE) - Chino Simplificado (ZH) - Portugués (PT) - Francés (FR) - Italiano (IT) Si el usuario no utiliza uno de estos idiomas, el sistema aplica el idioma default configurado por Esteve. ⚠️ LIMITACIÓN: Los idiomas listados han sido validados y soportados por los modelos Azure OpenAI utilizados. Idiomas fuera de esta lista están fuera del alcance de la solución, ya que no se puede garantizar su calidad ni funcionalidad. Esteve determinará el texto informativo que se mostrará a usuarios que intenten usar idiomas no soportados. | G21: Portal | H21: [ESTEVE]: revisar cómo aplicar la política de idiomas en relación a esta feature.
B22: FT.14 | C22: Agentes IA | D22: Configuración Portal de Agentes IA | E22: Comportamiento base compartido por agentes genéricos | F22: Cuando un usuario interactúa con cualquiera de los 10 agentes genéricos del portal, el sistema proporciona conversaciones en lenguaje natural con memoria de interacciones previas dentro de la misma sesión. El agente responde en el idioma de la consulta del usuario. - 7 agentes modelo básico (GPT-4o-mini): Consulta, Traducción, Consulta Documentos, Redactor Corporativo, Resumen Ejecutivo, Revisor Estilo, Preparación Reuniones - 3 agentes modelo avanzado (GPT-4o/o3): Researcher, Generador URS, Redactor RFPs Configuración de modelos: Los modelos Azure OpenAI asignados a cada agente son configurables post-despliegue por el Administrador. La disponibilidad de modelos específicos (incluyendo versiones más recientes como GPT-5) depende de: - Zona geográfica de la suscripción Azure - Límites de TPM (Tokens Por Minuto) del modelo en Azure - Capacidad de uso simultáneo entre usuarios La solución es escalable y permite cambiar modelos en el futuro según evolución del catálogo Azure OpenAI. Los 10 son agentes GENÉRICOS (operan sin contexto corporativo), diferenciados de agentes contextuales (FT.21-26) y del agente especializado Reactivos Químicos (FT.01-07). Gestión de disponibilidad: El portal muestra un aviso visible indicando que las respuestas de IA son orientativas y requieren validación del usuario. | G22: Agentes | H22: [ESTEVE]: RFP modelos distintos en función del departamento (Eva comprueba)
